Workbook
Name intercept: [1]Sheet2!$N$10
Name slope: [1]Sheet2!$N$9

Sheet General
A1: Units
A3: ppb | B3: µg/L
A4: cps | B4: counts per second
A6: Analysis of sample run using standard-sample data files (raw data) from:
A7: 19th Nov 2019
A8: 08th Jan 2020
A9: 27th Feb 2020
A12: Note:
A13: Concentrations selected for the calibration leading to leverage or bias. High concentration STDs are the point of influence because the disproportionately affect the position of the regression line.
A16: Suggested Changes (Kathrin)
A18: 1. Standards with at least seven different concentrations (including a blank)
A20: 2. Standard concentrations cover the range of sample concentrations and are evenly spaced across the calibration range to avoid leverage/bias
A22: 3. Lowest calibration standard should be approximately equal to estimated LOQ and the remaining standards cover the full range of sample concentrations

Sheet cobalt_Co
A1: Date | B1: No_cal | C1: Std_conc (ppb) | D1: Co 59 (cps) | E1: Co_59 (BLK corrected) | F1: SUMMARY OUTPUT | H1: ANOVA
A2: 43838 | B2: 1 | C2: 0 | D2: 66 | E2: =D2-$D$2 -> 0 | F2: Regression Statistics | I2: df | J2: SS | K2: MS | L2: F | M2: Significance F | O2: Coefficients | P2: SE | Q2: SD | R2: t Stat | S2: P-value | T2: Lower 95% | U2: Upper 95% | V2: Lower 95.0% | W2: Upper 95.0% | X2: LOD (µg/L) | Y2: LOQ (µg/L)
A3: 43838 | B3: 1 | C3: 0.01 | D3: 465 | E3: =D3-$D$2 -> 399 | F3: Multiple R | G3: 0.99998419 | H3: Regression | I3: 1 | J3: 35458642 | K3: 35458642 | L3: 94887.461 | M3: 7.5446836e-08 | N3: Intercept | O3: -71.839662 | P3: 22.670617 | Q3: =P3*SQRT(G7) -> 50.693041 | R3: -3.1688446 | S3: 0.050525607 | T3: -143.98768 | U3: 0.3083601 | V3: -143.98768 | W3: 0.3083601 | X3: =3.3*Q3/O4 -> 0.0035456048 | Y3: =10*Q3/O4 -> 0.010744257
A4: 43838 | B4: 1 | C4: 0.02 | D4: 901 | E4: =D4-$D$2 -> 835 | F4: R Square | G4: 0.99996838 | H4: Residual | I4: 3 | J4: 1121.0746 | K4: 373.69154 | N4: X Variable 1 | O4: 47181.523 | P4: 220.1965 | R4: 214.27009 | S4: 2.2415687e-07 | T4: 46480.76 | U4: 47882.287 | V4: 46480.76 | W4: 47882.287
A5: 43838 | B5: 1 | C5: 0.05 | D5: 2304.3787 | E5: =D5-$D$2 -> 2238.3787 | F5: Adjusted R Square | G5: 0.99995785 | H5: Total | I5: 4 | J5: 35459763
A6: 43838 | B6: 1 | C6: 0.1 | D6: 4706.6079 | E6: =D6-$D$2 -> 4640.6079 | F6: Standard Error | G6: 19.331103
A7: 43838 | B7: 1 | C7: 0.2 | D7: 9442.5744 | E7: =D7-$D$2 -> 9376.5744 | F7: Observations | G7: 5
A8: 43838 | B8: 2 | C8: 0 | D8: 56 | E8: =D8-$D$8 -> 0 | F8: Regression Statistics | H8: Regression | I8: 1 | J8: 53693439 | K8: 53693439 | L8: 45911.67 | M8: 2.2415687e-07 | N8: Intercept | O8: -7.7761194 | P8: 12.815068 | Q8: =P8*SQRT(G13) -> 28.655363 | R8: -0.60679502 | S8: 0.58682886 | T8: -48.559385 | U8: 33.007146 | V8: -48.559385 | W8: 33.007146 | X8: =3.3*Q8/O9 -> 0.0024663088 | Y8: =10*Q8/O9 -> 0.0074736632
A9: 43838 | B9: 2 | C9: 0.01 | D9: 412 | E9: =D9-$D$8 -> 356 | F9: Multiple R | G9: 0.99996733 | H9: Residual | I9: 3 | J9: 3508.4831 | K9: 1169.4944 | N9: X Variable 1 | O9: 38341.791 | P9: 124.47094 | R9: 308.03808 | S9: 7.5446836e-08 | T9: 37945.669 | U9: 38737.913 | V9: 37945.669 | W9: 38737.913
A10: 43838 | B10: 2 | C10: 0.02 | D10: 811 | E10: =D10-$D$8 -> 755 | F10: R Square | G10: 0.99993466 | H10: Total | I10: 4 | J10: 53696947
A11: 43838 | B11: 2 | C11: 0.05 | D11: 1988 | E11: =D11-$D$8 -> 1932 | F11: Adjusted R Square | G11: 0.99991288
A12: 43838 | B12: 2 | C12: 0.1 | D12: 3893 | E12: =D12-$D$8 -> 3837 | F12: Standard Error | G12: 34.197871
A13: 43838 | B13: 2 | C13: 0.2 | D13: 7707 | E13: =D13-$D$8 -> 7651 | F13: Observations | G13: 5
A14: 43838 | B14: 3 | C14: 0 | D14: 58 | E14: =D14-$D$14 -> 0 | F14: Regression Statistics | I14: df | J14: SS | K14: MS | L14: F | M14: Significance F | O14: Coefficients | P14: SE | Q14: SD | R14: t Stat | S14: P-value | T14: Lower 95% | U14: Upper 95% | V14: Lower 95.0% | W14: Upper 95.0%
A15: 43838 | B15: 3 | C15: 0.01 | D15: 400 | E15: =D15-$D$14 -> 342 | F15: Multiple R | G15: 0.99998329 | H15: Regression | I15: 1 | J15: 32289402 | K15: 32289402 | L15: 89737.98 | M15: 8.2033056e-08 | N15: Intercept | O15: -18.305141 | P15: 12.574946 | Q15: =P15*SQRT(G19) -> 28.118435 | R15: -1.4556834 | S15: 0.24149493 | T15: -58.324232 | U15: 21.71395 | V15: -58.324232 | W15: 21.71395 | X15: =3.3*Q15/O16 -> 0.0025360846 | Y15: =10*Q15/O16 -> 0.0076851047
A16: 43838 | B16: 3 | C16: 0.02 | D16: 783 | E16: =D16-$D$14 -> 725 | F16: R Square | G16: 0.99996657 | H16: Residual | I16: 3 | J16: 1079.4561 | K16: 359.81868 | N16: X Variable 1 | O16: 36588.226 | P16: 122.13867 | R16: 299.56298 | S16: 8.2033056e-08 | T16: 36199.526 | U16: 36976.925 | V16: 36199.526 | W16: 36976.925
A17: 43838 | B17: 3 | C17: 0.05 | D17: 1880 | E17: =D17-$D$14 -> 1822 | F17: Adjusted R Square | G17: 0.99995543 | H17: Total | I17: 4 | J17: 32290481
A18: 43838 | B18: 3 | C18: 0.1 | D18: 3672 | E18: =D18-$D$14 -> 3614 | F18: Standard Error | G18: 18.968887
A19: 43838 | B19: 3 | C19: 0.2 | D19: 7367 | E19: =D19-$D$14 -> 7309 | F19: Observations | G19: 5
A20: 43789 | B20: 4 | C20: 0 | D20: 84 | E20: =D20-$D$20 -> 0 | F20: Regression Statistics | H20: Regression | I20: 1 | J20: 19014122 | K20: 19014122 | L20: 4154.1357 | M20: 8.2295009e-06 | N20: Intercept | O20: 87.623546 | P20: 44.849962 | Q20: =P20*SQRT(G25) -> 100.28756 | R20: 1.9537039 | S20: 0.14574534 | T20: -55.10905 | U20: 230.35614 | V20: -55.10905 | W20: 230.35614 | X20: =3.3*Q20/O21 -> 0.011787224 | Y20: =10*Q20/O21 -> 0.035718861
A21: 43789 | B21: 4 | C21: 0.01 | D21: 403.75571 | E21: =D21-$D$20 -> 319.75571 | F21: Multiple R | G21: 0.99963911 | H21: Residual | I21: 3 | J21: 13731.464 | K21: 4577.1548 | N21: X Variable 1 | O21: 28076.921 | P21: 435.62134 | R21: 64.452585 | S21: 8.2295009e-06 | T21: 26690.58 | U21: 29463.263 | V21: 26690.58 | W21: 29463.263
A22: 43789 | B22: 4 | C22: 0.02 | D22: 697.51705 | E22: =D22-$D$20 -> 613.51705 | F22: R Square | G22: 0.99927835 | H22: Total | I22: 4 | J22: 19027853
A23: 43789 | B23: 4 | C23: 0.05 | D23: 1633.3434 | E23: =D23-$D$20 -> 1549.3434 | F23: Adjusted R Square | G23: 0.9990378
A24: 43789 | B24: 4 | C24: 0.1 | D24: 3049.0762 | E24: =D24-$D$20 -> 2965.0762 | F24: Standard Error | G24: 67.654673
A25: 43789 | B25: 4 | C25: 0.2 | D25: 5743.6554 | E25: =D25-$D$20 -> 5659.6554 | F25: Observations | G25: 5
A26: 43888 | B26: 5 | C26: 0 | D26: 78.500216 | E26: =D26-$D$26 -> 0 | F26: Regression Statistics | I26: df | J26: SS | K26: MS | L26: F | M26: Significance F | O26: Coefficients | P26: SE | Q26: SD | R26: t Stat | S26: P-value | T26: Lower 95% | U26: Upper 95% | V26: Lower 95.0% | W26: Upper 95.0%
A27: 43888 | B27: 5 | C27: 0.01 | D27: 539.51021 | E27: =D27-$D$26 -> 461.00999 | F27: Multiple R | G27: 0.99999736 | H27: Regression | I27: 1 | J27: 56166781 | K27: 56166781 | L27: 567349.57 | M27: 5.1605013e-09 | N27: Intercept | O27: -16.524574 | P27: 6.5959702 | Q27: =P27*SQRT(G31) -> 14.749038 | R27: -2.5052531 | S27: 0.087301615 | T27: -37.515895 | U27: 4.4667464 | V27: -37.515895 | W27: 4.4667464 | X27: =3.3*Q27/O28 -> 0.0010086175 | Y27: =10*Q27/O28 -> 0.0030564167
A28: 43888 | B28: 5 | C28: 0.02 | D28: 1021.5365 | E28: =D28-$D$26 -> 943.03632 | F28: R Square | G28: 0.99999471 | H28: Residual | I28: 3 | J28: 296.99563 | K28: 98.998543 | N28: X Variable 1 | O28: 48255.977 | P28: 64.065726 | R28: 753.22611 | S28: 5.1605013e-09 | T28: 48052.092 | U28: 48459.863 | V28: 48052.092 | W28: 48459.863
A29: 43888 | B29: 5 | C29: 0.05 | D29: 2478.9651 | E29: =D29-$D$26 -> 2400.4649 | F29: Adjusted R Square | G29: 0.99999295 | H29: Total | I29: 4 | J29: 56167078
A30: 43888 | B30: 5 | C30: 0.1 | D30: 4900.8409 | E30: =D30-$D$26 -> 4822.3407 | F30: Standard Error | G30: 9.9498011
A31: 43888 | B31: 5 | C31: 0.2 | D31: 9706.2968 | E31: =D31-$D$26 -> 9627.7966 | F31: Observations | G31: 5
A32: 43888 | B32: 6 | C32: 0 | D32: 81.750235 | E32: =D32-$D$32 -> 0 | F32: Regression Statistics | I32: df | J32: SS | K32: MS | L32: F | M32: Significance F | O32: Coefficients | P32: SE | Q32: SD | R32: t Stat | S32: P-value | T32: Lower 95% | U32: Upper 95% | V32: Lower 95.0% | W32: Upper 95.0%
A33: 43888 | B33: 6 | C33: 0.01 | D33: 491.00845 | E33: =D33-$D$32 -> 409.25821 | F33: Multiple R | G33: 0.99994224 | H33: Regression | I33: 1 | J33: 41443234 | K33: 41443234 | L33: 25969.34 | M33: 5.2688904e-07 | N33: Intercept | O33: 3.3573857 | P33: 26.482601 | Q33: =P33*SQRT(G37) -> 59.216897 | R33: 0.12677703 | S33: 0.9071368 | T33: -80.922071 | U33: 87.636842 | V33: -80.922071 | W33: 87.636842 | X33: =3.3*Q33/O34 -> 0.0047143456 | Y33: =10*Q33/O34 -> 0.014285896
A34: 43888 | B34: 6 | C34: 0.02 | D34: 891.27783 | E34: =D34-$D$32 -> 809.5276 | F34: R Square | G34: 0.99988449 | H34: Residual | I34: 3 | J34: 4787.5572 | K34: 1595.8524 | N34: X Variable 1 | O34: 41451.301 | P34: 257.22176 | R34: 161.15006 | S34: 5.2688904e-07 | T34: 40632.707 | U34: 42269.896 | V34: 40632.707 | W34: 42269.896
A35: 43888 | B35: 6 | C35: 0.05 | D35: 2215.4218 | E35: =D35-$D$32 -> 2133.6716 | F35: Adjusted R Square | G35: 0.99984599 | H35: Total | I35: 4 | J35: 41448022
A36: 43888 | B36: 6 | C36: 0.1 | D36: 4201.1177 | E36: =D36-$D$32 -> 4119.3674 | F36: Standard Error | G36: 39.948121
A37: 43888 | B37: 6 | C37: 0.2 | D37: 8378.2068 | E37: =D37-$D$32 -> 8296.4566 | F37: Observations | G37: 5 | W37: MEAN | X37: =AVERAGE(X33,X27,X20,X15,X8,X3) -> 0.0043430309 | Y37: =AVERAGE(Y33,Y27,Y20,Y15,Y8,Y3) -> 0.0131607
E41: Concentration _calibration methods | K41: Concentrations relative to P.Elmer instrument data
A42: Sample ID | B42: Raw int (cps) | C42: Ga_int | E42: Calb_ no "0" intercept | F42: Calb_ "0" intercept | G42: Weighted | H42: Conc_trend | I42: Calb_ P.Elmer | J42: Conc_Uncertainty _P.Elmer | K42: Calb_ no "0" intercept | L42: Calb_ "0" intercept | M42: Weighted | N42: Conc_trend
A43: 7014562 | B43: 414.75604 | C43: 0.89450954 | E43: =((B43-$D$2+71.471)/47154)/(C43*100%)*$B$62 -> 0.49813892 | F43: =((B43-$D$2)/46641)/(C43*100%)*$B$62 -> 0.41796403 | G43: =0.00933150542012172/(C43*100%)*50 -> 0.52159899 | H43: =TREND($C$2:$C$7,$E$2:$E$7,B43)/(C43*100%)*$B$62 -> 0.57679694 | I43: 0.46499121 | J43: 0.053229486 | K43: =100-(I43/E43*100) -> 6.6543106 | L43: =(I43/F43*100)-100 -> 11.251491 | M43: =100-(I43/G43*100) -> 10.852739 | N43: =100-(I43/H43*100) -> 19.383898
...

Sheet nickel_Ni
A1: Date | B1: No_cal | C1: Std_conc (ppb) | D1: Ni 60 (cps) | E1: Ni_60 (BLK corrected) | F1: SUMMARY OUTPUT | H1: ANOVA
A2: 43838 | B2: 1 | C2: 0 | D2: 41 | E2: =D2-$D$2 -> 0 | F2: Regression Statistics | I2: df | J2: SS | K2: MS | L2: F | M2: Significance F | O2: Coefficients | P2: SE | Q2: SD | R2: t Stat | S2: P-value | T2: Lower 95% | U2: Upper 95% | V2: Lower 95.0% | W2: Upper 95.0% | X2: LOD (µg/L) | Y2: LOQ (µg/L)
A3: 43838 | B3: 1 | C3: 0.05 | D3: 491.73415 | E3: =D3-$D$2 -> 450.73415 | F3: Multiple R | G3: 0.99999121 | H3: Regression | I3: 1 | J3: 53479639 | K3: 53479639 | L3: 170656.18 | M3: 3.1280851e-08 | N3: Intercept | O3: -21.605678 | P3: 11.735389 | Q3: =P3*SQRT(G7) -> 26.241128 | R3: -1.8410704 | S3: 0.16286431 | T3: -58.952924 | U3: 15.741569 | V3: -58.952924 | W3: 15.741569 | X3: =3.3*Q3/O4 -> 0.0091951934 | Y3: =10*Q3/O4 -> 0.027864223
A4: 43838 | B4: 1 | C4: 0.1 | D4: 954.48535 | E4: =D4-$D$2 -> 913.48535 | F4: R Square | G4: 0.99998242 | H4: Residual | I4: 3 | J4: 940.12955 | K4: 313.37652 | N4: X Variable 1 | O4: 9417.4989 | P4: 22.796836 | R4: 413.10553 | S4: 3.1280851e-08 | T4: 9344.9492 | U4: 9490.0486 | V4: 9344.9492 | W4: 9490.0486
A5: 43838 | B5: 1 | C5: 0.25 | D5: 2394 | E5: =D5-$D$2 -> 2353 | F5: Adjusted R Square | G5: 0.99997656 | H5: Total | I5: 4 | J5: 53480579
A6: 43838 | B6: 1 | C6: 0.5 | D6: 4707 | E6: =D6-$D$2 -> 4666 | F6: Standard Error | G6: 17.702444
A7: 43838 | B7: 1 | C7: 1 | D7: 9443 | E7: =D7-$D$2 -> 9402 | F7: Observations | G7: 5
A8: 43838 | B8: 2 | C8: 0 | D8: 51 | E8: =D8-$D$8 -> 0 | F8: Regression Statistics | I8: df | J8: SS | K8: MS | L8: F | M8: Significance F | O8: Coefficients | P8: SE | Q8: SD | R8: t Stat | S8: P-value | T8: Lower 95% | U8: Upper 95% | V8: Lower 95.0% | W8: Upper 95.0%
A9: 43838 | B9: 2 | C9: 0.05 | D9: 432 | E9: =D9-$D$8 -> 381 | F9: Multiple R | G9: 0.99983167 | H9: Regression | I9: 1 | J9: 43006543 | K9: 43006543 | L9: 8908.5608 | M9: 2.6217058e-06 | N9: Intercept | O9: -37.766169 | P9: 46.060407 | Q9: =P9*SQRT(G13) -> 102.9942 | R9: -0.81992695 | S9: 0.4723359 | T9: -184.35094 | U9: 108.8186 | V9: -184.35094 | W9: 108.8186 | X9: =3.3*Q9/O10 -> 0.040245572 | Y9: =10*Q9/O10 -> 0.12195628
A10: 43838 | B10: 2 | C10: 0.1 | D10: 884 | E10: =D10-$D$8 -> 833 | F10: R Square | G10: 0.99966336 | H10: Residual | I10: 3 | J10: 14482.657 | K10: 4827.5522 | N10: X Variable 1 | O10: 8445.1741 | P10: 89.475644 | R10: 94.385172 | S10: 2.6217058e-06 | T10: 8160.4227 | U10: 8729.9256 | V10: 8160.4227 | W10: 8729.9256
A11: 43838 | B11: 2 | C11: 0.25 | D11: 2166 | E11: =D11-$D$8 -> 2115 | F11: Adjusted R Square | G11: 0.99955114 | H11: Total | I11: 4 | J11: 43021025
A12: 43838 | B12: 2 | C12: 0.5 | D12: 4133 | E12: =D12-$D$8 -> 4082 | F12: Standard Error | G12: 69.480589
A13: 43838 | B13: 2 | C13: 1 | D13: 8497 | E13: =D13-$D$8 -> 8446 | F13: Observations | G13: 5
A14: 43838 | B14: 3 | C14: 0 | D14: 47 | E14: =D14-$D$14 -> 0 | F14: Regression Statistics | I14: df | J14: SS | K14: MS | L14: F | M14: Significance F | O14: Coefficients | P14: SE | Q14: SD | R14: t Stat | S14: P-value | T14: Lower 95% | U14: Upper 95% | V14: Lower 95.0% | W14: Upper 95.0%
A15: 43838 | B15: 3 | C15: 0.05 | D15: 424 | E15: =D15-$D$14 -> 377 | F15: Multiple R | G15: 0.99999622 | H15: Regression | I15: 1 | J15: 38980010 | K15: 38980010 | L15: 396686.75 | M15: 8.8266368e-09 | N15: Intercept | O15: -13.844113 | P15: 6.571453 | Q15: =P15*SQRT(G19) -> 14.694216 | R15: -2.106705 | S15: 0.12576037 | T15: -34.757409 | U15: 7.0691836 | V15: -34.757409 | W15: 7.0691836 | X15: =3.3*Q15/O16 -> 0.0060311208 | Y15: =10*Q15/O16 -> 0.018276124
A16: 43838 | B16: 3 | C16: 0.1 | D16: 837 | E16: =D16-$D$14 -> 790 | F16: R Square | G16: 0.99999244 | H16: Residual | I16: 3 | J16: 294.79187 | K16: 98.263958 | N16: X Variable 1 | O16: 8040.1161 | P16: 12.765519 | R16: 629.83073 | S16: 8.8266368e-09 | T16: 7999.4905 | U16: 8080.7417 | V16: 7999.4905 | W16: 8080.7417
A17: 43838 | B17: 3 | C17: 0.25 | D17: 2053 | E17: =D17-$D$14 -> 2006 | F17: Adjusted R Square | G17: 0.99998992 | H17: Total | I17: 4 | J17: 38980305
A18: 43838 | B18: 3 | C18: 0.5 | D18: 4060 | E18: =D18-$D$14 -> 4013 | F18: Standard Error | G18: 9.9128179
A19: 43838 | B19: 3 | C19: 1 | D19: 8068 | E19: =D19-$D$14 -> 8021 | F19: Observations | G19: 5
A20: 43789 | B20: 1 | C20: 0 | D20: 43.7 | E20: =D20-$D$20 -> 0 | F20: Regression Statistics | I20: df | J20: SS | K20: MS | L20: F | M20: Significance F | O20: Coefficients | P20: SE | Q20: SD | R20: t Stat | S20: P-value | T20: Lower 95% | U20: Upper 95% | V20: Lower 95.0% | W20: Upper 95.0%
A21: 43789 | B21: 1 | C21: 0.05 | D21: 379.8 | E21: =D21-$D$20 -> 336.1 | F21: Multiple R | G21: 0.99967873 | H21: Regression | I21: 1 | J21: 24359586 | K21: 24359586 | L21: 4666.7899 | M21: 6.9120753e-06 | N21: Intercept | O21: 70.522222 | P21: 47.894993 | Q21: =P21*SQRT(G25) -> 107.09646 | R21: 1.4724341 | S21: 0.23730585 | T21: -81.90102 | U21: 222.94546 | V21: -81.90102 | W21: 222.94546 | X21: =3.3*Q21/O22 -> 0.055604861 | Y21: =10*Q21/O22 -> 0.16849958
A22: 43789 | B22: 1 | C22: 0.1 | D22: 709.6 | E22: =D22-$D$20 -> 665.9 | F22: R Square | G22: 0.99935757 | H22: Residual | I22: 3 | J22: 15659.321 | K22: 5219.7735 | N22: X Variable 1 | O22: 6355.8889 | P22: 93.039458 | R22: 68.313907 | S22: 6.9120753e-06 | T22: 6059.7958 | U22: 6651.982 | V22: 6059.7958 | W22: 6651.982
A23: 43789 | B23: 1 | C23: 0.25 | D23: 1772.9 | E23: =D23-$D$20 -> 1729.2 | F23: Adjusted R Square | G23: 0.99914343 | H23: Total | I23: 4 | J23: 24375245
A24: 43789 | B24: 1 | C24: 0.5 | D24: 3359.2 | E24: =D24-$D$20 -> 3315.5 | F24: Standard Error | G24: 72.248
A25: 43789 | B25: 1 | C25: 1 | D25: 6425.8 | E25: =D25-$D$20 -> 6382.1 | F25: Observations | G25: 5
A26: 43888 | B26: 1 | C26: 0 | D26: 24.436686 | E26: =D26-$D$26 -> 0 | F26: Regression Statistics | I26: df | J26: SS | K26: MS | L26: F | M26: Significance F | O26: Coefficients | P26: SE | Q26: SD | R26: t Stat | S26: P-value | T26: Lower 95% | U26: Upper 95% | V26: Lower 95.0% | W26: Upper 95.0%
A27: 43888 | B27: 1 | C27: 0.05 | D27: 563.46157 | E27: =D27-$D$26 -> 539.02489 | F27: Multiple R | G27: 0.99989314 | H27: Regression | I27: 1 | J27: 69504136 | K27: 69504136 | L27: 14035.228 | M27: 1.3259592e-06 | N27: Intercept | O27: -33.899359 | P27: 46.650883 | Q27: =P27*SQRT(G31) -> 104.31455 | R27: -0.7266606 | S27: 0.52000074 | T27: -182.36329 | U27: 114.56457 | V27: -182.36329 | W27: 114.56457 | X27: =3.3*Q27/O28 -> 0.03206359 | Y27: =10*Q27/O28 -> 0.097162394
A28: 43888 | B28: 1 | C28: 0.1 | D28: 1109.489 | E28: =D28-$D$26 -> 1085.0524 | F28: R Square | G28: 0.9997863 | H28: Residual | I28: 3 | J28: 14856.361 | K28: 4952.1203 | N28: X Variable 1 | O28: 10736.103 | P28: 90.622687 | R28: 118.47037 | S28: 1.3259592e-06 | T28: 10447.701 | U28: 11024.505 | V28: 10447.701 | W28: 11024.505
A29: 43888 | B29: 1 | C29: 0.25 | D29: 2631.8365 | E29: =D29-$D$26 -> 2607.3998 | F29: Adjusted R Square | G29: 0.99971506 | H29: Total | I29: 4 | J29: 69518992
A30: 43888 | B30: 1 | C30: 0.5 | D30: 5272.4378 | E30: =D30-$D$26 -> 5248.0011 | F30: Standard Error | G30: 70.371303
A31: 43888 | B31: 1 | C31: 1 | D31: 10774.057 | E31: =D31-$D$26 -> 10749.621 | F31: Observations | G31: 5
A32: 43888 | B32: 2 | C32: 0 | D32: 33.967095 | E32: =D32-$D$32 -> 0 | F32: Regression Statistics | I32: df | J32: SS | K32: MS | L32: F | M32: Significance F | O32: Coefficients | P32: SE | Q32: SD | R32: t Stat | S32: P-value | T32: Lower 95% | U32: Upper 95% | V32: Lower 95.0% | W32: Upper 95.0%
A33: 43888 | B33: 2 | C33: 0.05 | D33: 514.94507 | E33: =D33-$D$32 -> 480.97797 | F33: Multiple R | G33: 0.99998082 | H33: Regression | I33: 1 | J33: 49949242 | K33: 49949242 | L33: 78185.011 | M33: 1.0087081e-07 | N33: Intercept | O33: 31.761108 | P33: 16.75587 | Q33: =P33*SQRT(G37) -> 37.467264 | R33: 1.8955213 | S33: 0.15431147 | T33: -21.563549 | U33: 85.085764 | V33: -21.563549 | W33: 85.085764 | X33: =3.3*Q33/O34 -> 0.013585015 | Y33: =10*Q33/O34 -> 0.041166713
A34: 43888 | B34: 2 | C34: 0.1 | D34: 954.22459 | E34: =D34-$D$32 -> 920.25749 | F34: R Square | G34: 0.99996163 | H34: Residual | I34: 3 | J34: 1916.5787 | K34: 638.85956 | N34: X Variable 1 | O34: 9101.3495 | P34: 32.549479 | R34: 279.61583 | S34: 1.0087081e-07 | T34: 8997.7626 | U34: 9204.9365 | V34: 8997.7626 | W34: 9204.9365
A35: 43888 | B35: 2 | C35: 0.25 | D35: 2378.0537 | E35: =D35-$D$32 -> 2344.0866 | F35: Adjusted R Square | G35: 0.99994884 | H35: Total | I35: 4 | J35: 49951158
A36: 43888 | B36: 2 | C36: 0.5 | D36: 4610.9865 | E36: =D36-$D$32 -> 4577.0194 | F36: Standard Error | G36: 25.275671
A37: 43888 | B37: 2 | C37: 1 | D37: 9162.9954 | E37: =D37-$D$32 -> 9129.0283 | F37: Observations | G37: 5 | W37: MEAN | X37: =AVERAGE(X33,X27,X21,X15,X9,X3) -> 0.026120892 | Y37: =AVERAGE(Y33,Y27,Y21,Y15,Y9,Y3) -> 0.079154218
E40: Concentration _calibration methods | K40: Concentrations relative to P.Elmer instrument data
A41: Sample ID | B41: Raw intensity | C41: Ga_int | E41: Calb_ no "0" intercept | F41: Calb_ "0" intercept | G41: Weighted | H41: Conc_trend | I41: Calb_ P.Elmer | J41: Conc_Uncertainty _P.Elmer | K41: Calb_ no "0" intercept | L41: Calb_ "0" intercept | M41: Weighted | N41: Conc_trend
A42: 7014562 | B42: 231.8513 | C42: 0.89450954 | E42: =((B42-$D$2+15.009)/9408)/(C42*100%) -> 0.024461907 | F42: =((B42-$D$2)/9386.5)/(C42*100%)*$B$114 -> 1.1365184 | H42: =TREND($C$2:$C$7,$E$2:$E$7,B42)/(C42*100%)*$B$114 -> 1.4670093 | I42: 1.1714882 | K42: =100-(I42/E42*100) -> -4689.0307 | L42: =(I42/F42*100)-100 -> 3.0769294 | M42: =(J42/G42*100)-100 -> #DIV/0! | N42: =(I42/H42*100)-100 -> -20.144457
...

Sheet zinc_Zn
A1: Date | B1: No_cal | C1: Std_conc (ppb) | D1: Zn 64 (cps) | E1: Zn_64 (BLK corrected) | F1: SUMMARY OUTPUT | H1: ANOVA
A2: 43838 | B2: 1 | C2: 0 | D2: 542 | E2: =D2-$D$2 -> 0 | F2: Regression Statistics | I2: df | J2: SS | K2: MS | L2: F | M2: Significance F | O2: Coefficients | P2: SE | Q2: SD | R2: t Stat | S2: P-value | T2: Lower 95% | U2: Upper 95% | V2: Lower 95.0% | W2: Upper 95.0% | X2: LOD (µg/L) | Y2: LOQ (µg/L)
A3: 43838 | B3: 1 | C3: 1 | D3: 5778 | E3: =D3-$D$2 -> 5236 | F3: Multiple R | G3: 0.9999825 | H3: Regression | I3: 1 | J3: 7.0935443e+09 | K3: 7.0935443e+09 | L3: 85727.159 | M3: 8.7856695e-08 | N3: Intercept | O3: -358.72139 | P3: 190.69386 | Q3: =P3*SQRT(G7) -> 426.40443 | R3: -1.8811376 | S3: 0.15651893 | T3: -965.59436 | U3: 248.15157 | V3: -965.59436 | W3: 248.15157 | X3: =3.3*Q3/O4 -> 0.25947329 | Y3: =10*Q3/O4 -> 0.7862827
A4: 43838 | B4: 1 | C4: 2 | D4: 11162 | E4: =D4-$D$2 -> 10620 | F4: R Square | G4: 0.99996501 | H4: Residual | I4: 3 | J4: 248236.77 | K4: 82745.59 | N4: X Variable 1 | O4: 5423.0423 | P4: 18.521825 | R4: 292.79201 | S4: 8.7856695e-08 | T4: 5364.0976 | U4: 5481.987 | V4: 5364.0976 | W4: 5481.987
A5: 43838 | B5: 1 | C5: 5 | D5: 27177 | E5: =D5-$D$2 -> 26635 | F5: Adjusted R Square | G5: 0.99995334 | H5: Total | I5: 4 | J5: 7.0937925e+09
A6: 43838 | B6: 1 | C6: 10 | D6: 54031 | E6: =D6-$D$2 -> 53489 | F6: Standard Error | G6: 287.65533
A7: 43838 | B7: 1 | C7: 20 | D7: 108844 | E7: =D7-$D$2 -> 108302 | F7: Observations | G7: 5
A8: 43838 | B8: 2 | C8: 0 | D8: 714 | E8: =D8-$D$8 -> 0 | F8: Regression Statistics | I8: df | J8: SS | K8: MS | L8: F | M8: Significance F | O8: Coefficients | P8: SE | Q8: SD | R8: t Stat | S8: P-value | T8: Lower 95% | U8: Upper 95% | V8: Lower 95.0% | W8: Upper 95.0%
A9: 43838 | B9: 2 | C9: 1 | D9: 5265 | E9: =D9-$D$8 -> 4551 | F9: Multiple R | G9: 0.99995316 | H9: Regression | I9: 1 | J9: 5.5979996e+09 | K9: 5.5979996e+09 | L9: 32018.965 | M9: 3.8486728e-07 | N9: Intercept | O9: -361.91045 | P9: 277.18969 | Q9: =P9*SQRT(G13) -> 619.81498 | R9: -1.3056418 | S9: 0.28277587 | T9: -1244.0517 | U9: 520.23085 | V9: -1244.0517 | W9: 520.23085 | X9: =3.3*Q9/O10 -> 0.42456895 | Y9: =10*Q9/O10 -> 1.2865726
A10: 43838 | B10: 2 | C10: 2 | D10: 10120 | E10: =D10-$D$8 -> 9406 | F10: R Square | G10: 0.99990631 | H10: Residual | I10: 3 | J10: 524501.61 | K10: 174833.87 | N10: X Variable 1 | O10: 4817.5672 | P10: 26.923042 | R10: 178.93844 | S10: 3.8486728e-07 | T10: 4731.886 | U10: 4903.2483 | V10: 4731.886 | W10: 4903.2483
A11: 43838 | B11: 2 | C11: 5 | D11: 24585 | E11: =D11-$D$8 -> 23871 | F11: Adjusted R Square | G11: 0.99987509 | H11: Total | I11: 4 | J11: 5.5985241e+09
A12: 43838 | B12: 2 | C12: 10 | D12: 47890 | E12: =D12-$D$8 -> 47176 | F12: Standard Error | G12: 418.1314
A13: 43838 | B13: 2 | C13: 20 | D13: 96968 | E13: =D13-$D$8 -> 96254 | F13: Observations | G13: 5
A14: 43838 | B14: 3 | C14: 0 | D14: 679 | E14: =D14-$D$14 -> 0 | F14: Regression Statistics | I14: df | J14: SS | K14: MS | L14: F | M14: Significance F | O14: Coefficients | P14: SE | Q14: SD | R14: t Stat | S14: P-value | T14: Lower 95% | U14: Upper 95% | V14: Lower 95.0% | W14: Upper 95.0%
A15: 43838 | B15: 3 | C15: 1 | D15: 5019 | E15: =D15-$D$14 -> 4340 | F15: Multiple R | G15: 0.99997486 | H15: Regression | I15: 1 | J15: 4.9201839e+09 | K15: 4.9201839e+09 | L15: 59663.543 | M15: 1.5131465e-07 | N15: Intercept | O15: -106 | P15: 190.37084 | Q15: =P15*SQRT(G19) -> 425.68214 | R15: -0.55680796 | S15: 0.61649953 | T15: -711.84498 | U15: 499.84498 | V15: -711.84498 | W15: 499.84498 | X15: =3.3*Q15/O16 -> 0.31102647 | Y15: =10*Q15/O16 -> 0.94250447
A16: 43838 | B16: 3 | C16: 2 | D16: 9565 | E16: =D16-$D$14 -> 8886 | F16: R Square | G16: 0.99994972 | H16: Residual | I16: 3 | J16: 247396.5 | K16: 82465.5 | N16: X Variable 1 | O16: 4516.5 | P16: 18.490451 | R16: 244.26122 | S16: 1.5131465e-07 | T16: 4457.6551 | U16: 4575.3449 | V16: 4457.6551 | W16: 4575.3449
A17: 43838 | B17: 3 | C17: 5 | D17: 23512 | E17: =D17-$D$14 -> 22833 | F17: Adjusted R Square | G17: 0.99993296 | H17: Total | I17: 4 | J17: 4.9204313e+09
A18: 43838 | B18: 3 | C18: 10 | D18: 45411 | E18: =D18-$D$14 -> 44732 | F18: Standard Error | G18: 287.16807
A19: 43838 | B19: 3 | C19: 20 | D19: 90985 | E19: =D19-$D$14 -> 90306 | F19: Observations | G19: 5
A20: 43789 | B20: 1 | C20: 0 | D20: 234.75193 | E20: =D20-$D$20 -> 0 | F20: Regression Statistics | I20: df | J20: SS | K20: MS | L20: F | M20: Significance F | O20: Coefficients | P20: SE | Q20: SD | R20: t Stat | S20: P-value | T20: Lower 95% | U20: Upper 95% | V20: Lower 95.0% | W20: Upper 95.0%
A21: 43789 | B21: 1 | C21: 1 | D21: 8852.7423 | E21: =D21-$D$20 -> 8617.9904 | F21: Multiple R | G21: 0.99889908 | H21: Regression | I21: 1 | J21: 3.6125341e+09 | K21: 3.6125341e+09 | L21: 1360.2425 | M21: 4.3842777e-05 | N21: Intercept | O21: 2609.5955 | P21: 1080.3441 | Q21: =P21*SQRT(G25) -> 2415.7228 | R21: 2.4155225 | S21: 0.094547515 | T21: -828.54156 | U21: 6047.7325 | V21: -828.54156 | W21: 6047.7325 | X21: =3.3*Q21/O22 -> 2.0598885 | Y21: =10*Q21/O22 -> 6.2420864
A22: 43789 | B22: 1 | C22: 2 | D22: 8852.7423 | E22: =D22-$D$20 -> 8617.9904 | F22: R Square | G22: 0.99779936 | H22: Residual | I22: 3 | J22: 7967404.9 | K22: 2655801.6 | N22: X Variable 1 | O22: 3870.0567 | P22: 104.93229 | R22: 36.881465 | S22: 4.3842777e-05 | T22: 3536.1153 | U22: 4203.9981 | V22: 3536.1153 | W22: 4203.9981
A23: 43789 | B23: 1 | C23: 5 | D23: 21627.365 | E23: =D23-$D$20 -> 21392.613 | F23: Adjusted R Square | G23: 0.99706582 | H23: Total | I23: 4 | J23: 3.6205015e+09
A24: 43789 | B24: 1 | C24: 10 | D24: 41450.063 | E24: =D24-$D$20 -> 41215.312 | F24: Standard Error | G24: 1629.663
A25: 43789 | B25: 1 | C25: 20 | D25: 80500.978 | E25: =D25-$D$20 -> 80266.226 | F25: Observations | G25: 5
A26: 43888 | B26: 1 | C26: 0 | D26: 345.00419 | E26: =D26-$D$26 -> 0 | F26: Regression Statistics | I26: df | J26: SS | K26: MS | L26: F | M26: Significance F | O26: Coefficients | P26: SE | Q26: SD | R26: t Stat | S26: P-value | T26: Lower 95% | U26: Upper 95% | V26: Lower 95.0% | W26: Upper 95.0%
A27: 43888 | B27: 1 | C27: 1 | D27: 6003.0113 | E27: =D27-$D$26 -> 5658.0071 | F27: Multiple R | G27: 0.99997764 | H27: Regression | I27: 1 | J27: 8.0294431e+09 | K27: 8.0294431e+09 | L27: 67073.291 | M27: 1.2694717e-07 | N27: Intercept | O27: -232.50823 | P27: 229.36766 | Q27: =P27*SQRT(G31) -> 512.88168 | R27: -1.0136923 | S27: 0.38537918 | T27: -962.45849 | U27: 497.44204 | V27: -962.45849 | W27: 497.44204 | X27: =3.3*Q27/O28 -> 0.2933439 | Y27: =10*Q27/O28 -> 0.88892092
A28: 43888 | B28: 1 | C28: 2 | D28: 11681.024 | E28: =D28-$D$26 -> 11336.02 | F28: R Square | G28: 0.99995527 | H28: Residual | I28: 3 | J28: 359134.45 | K28: 119711.48 | N28: X Variable 1 | O28: 5769.711 | P28: 22.278157 | R28: 258.98512 | S28: 1.2694717e-07 | T28: 5698.812 | U28: 5840.61 | V28: 5698.812 | W28: 5840.61
A29: 43888 | B29: 1 | C29: 5 | D29: 29121.406 | E29: =D29-$D$26 -> 28776.402 | F29: Adjusted R Square | G29: 0.99994037 | H29: Total | I29: 4 | J29: 8.0298022e+09
A30: 43888 | B30: 1 | C30: 10 | D30: 57287.153 | E30: =D30-$D$26 -> 56942.149 | F30: Standard Error | G30: 345.99347
A31: 43888 | B31: 1 | C31: 20 | D31: 115718.9 | E31: =D31-$D$26 -> 115373.9 | F31: Observations | G31: 5
A32: 43888 | B32: 2 | C32: 0 | D32: 353.00437 | E32: =D32-$D$32 -> 0 | F32: Regression Statistics | I32: df | J32: SS | K32: MS | L32: F | M32: Significance F | O32: Coefficients | P32: SE | Q32: SD | R32: t Stat | S32: P-value | T32: Lower 95% | U32: Upper 95% | V32: Lower 95.0% | W32: Upper 95.0%
A33: 43888 | B33: 2 | C33: 1 | D33: 5478.3008 | E33: =D33-$D$32 -> 5125.2964 | F33: Multiple R | G33: 0.99999336 | H33: Regression | I33: 1 | J33: 6.0434067e+09 | K33: 6.0434067e+09 | L33: 225822.44 | M33: 2.0550064e-08 | N33: Intercept | O33: 82.430959 | P33: 108.44802 | Q33: =P33*SQRT(G37) -> 242.49715 | R33: 0.76009647 | S33: 0.50247374 | T33: -262.69905 | U33: 427.56097 | V33: -262.69905 | W33: 427.56097 | X33: =3.3*Q33/O34 -> 0.1598705 | Y33: =10*Q33/O34 -> 0.48445605
A34: 43888 | B34: 2 | C34: 2 | D34: 10379.019 | E34: =D34-$D$32 -> 10026.015 | F34: R Square | G34: 0.99998672 | H34: Residual | I34: 3 | J34: 80285.289 | K34: 26761.763 | N34: X Variable 1 | O34: 5005.5552 | P34: 10.533403 | R34: 475.20779 | S34: 2.0550064e-08 | T34: 4972.0333 | U34: 5039.0772 | V34: 4972.0333 | W34: 5039.0772
A35: 43888 | B35: 2 | C35: 5 | D35: 25632.73 | E35: =D35-$D$32 -> 25279.725 | F35: Adjusted R Square | G35: 0.99998229 | H35: Total | I35: 4 | J35: 6.043487e+09
A36: 43888 | B36: 2 | C36: 10 | D36: 50287.37 | E36: =D36-$D$32 -> 49934.365 | F36: Standard Error | G36: 163.59023
A37: 43888 | B37: 2 | C37: 20 | D37: 100610.86 | E37: =D37-$D$32 -> 100257.85 | F37: Observations | G37: 5
E40: Concentration _calibration methods | K40: Concentrations relative to P.Elmer instrument data
A41: Sample ID | B41: Raw intensity | C41: Ga_int | E41: Calb_ no "0" intercept | F41: Calb_ "0" intercept | G41: Weighted | H41: Conc_trend | I41: Calb_ P.Elmer | J41: Conc_Uncertainty _P.Elmer | K41: Calb_ no "0" intercept | L41: Calb_ "0" intercept | M41: Weighted | N41: Conc_trend
A42: 7014562 | B42: 308637.76 | C42: 0.89450954 | E42: =((B42-$D$2+249.2)/5415.2)/(C42*100%)*$B$114 -> 3182.7856 | F42: =((B42-$D$2)/5397.3)/(C42*100%)*$B$114 -> 3190.7604 | H42: =TREND($C$2:$C$7,$E$2:$E$7,B42-$D$2)/(C42*100%)*$B$114 -> 3182.6789 | I42: 3223.4654 | J42: 0.011433498 | K42: =100-(I42/E42*100) -> -1.2781205 | L42: =100-(I42/F42*100) -> -1.0249916 | N42: =100-(I42/H42*100) -> -1.2815159
...

Sheet copper_Cu
A1: Date | B1: No_cal | C1: Std_conc (ppb) | D1: Cu65 (cps) | E1: Cu65 (BLK corrected) | F1: SUMMARY OUTPUT | H1: ANOVA
A2: 43838 | B2: 1 | C2: 0 | D2: 542 | E2: =D2-$D$2 -> 0 | F2: Regression Statistics | I2: df | J2: SS | K2: MS | L2: F | M2: Significance F | O2: Coefficients | P2: SE | Q2: SD | R2: t Stat | S2: P-value | T2: Lower 95% | U2: Upper 95% | V2: Lower 95.0% | W2: Upper 95.0% | X2: LOD (µg/L) | Y2: LOQ (µg/L)
A3: 43838 | B3: 1 | C3: 0.25 | D3: 5778 | E3: =D3-$D$2 -> 5236 | F3: Multiple R | G3: 0.9999825 | H3: Regression | I3: 1 | J3: 7.0935443e+09 | K3: 7.0935443e+09 | L3: 85727.159 | M3: 8.7856695e-08 | N3: Intercept | O3: -358.72139 | P3: 190.69386 | Q3: =P3*SQRT(G7) -> 426.40443 | R3: -1.8811376 | S3: 0.15651893 | T3: -965.59436 | U3: 248.15157 | V3: -965.59436 | W3: 248.15157 | X3: =3.3*Q3/O4 -> 0.064868323 | Y3: =10*Q3/O4 -> 0.19657067
A4: 43838 | B4: 1 | C4: 0.5 | D4: 11162 | E4: =D4-$D$2 -> 10620 | F4: R Square | G4: 0.99996501 | H4: Residual | I4: 3 | J4: 248236.77 | K4: 82745.59 | N4: X Variable 1 | O4: 21692.169 | P4: 74.0873 | R4: 292.79201 | S4: 8.7856695e-08 | T4: 21456.39 | U4: 21927.948 | V4: 21456.39 | W4: 21927.948
A5: 43838 | B5: 1 | C5: 1.25 | D5: 27177 | E5: =D5-$D$2 -> 26635 | F5: Adjusted R Square | G5: 0.99995334 | H5: Total | I5: 4 | J5: 7.0937925e+09
A6: 43838 | B6: 1 | C6: 2.5 | D6: 54031 | E6: =D6-$D$2 -> 53489 | F6: Standard Error | G6: 287.65533
A7: 43838 | B7: 1 | C7: 5 | D7: 108844 | E7: =D7-$D$2 -> 108302 | F7: Observations | G7: 5
A8: 43838 | B8: 2 | C8: 0 | D8: 714 | E8: =D8-$D$8 -> 0 | F8: Regression Statistics | I8: df | J8: SS | K8: MS | L8: F | M8: Significance F | O8: Coefficients | P8: SE | Q8: SD | R8: t Stat | S8: P-value | T8: Lower 95% | U8: Upper 95% | V8: Lower 95.0% | W8: Upper 95.0%
A9: 43838 | B9: 2 | C9: 0.25 | D9: 5265 | E9: =D9-$D$8 -> 4551 | F9: Multiple R | G9: 0.99995316 | H9: Regression | I9: 1 | J9: 5.5979996e+09 | K9: 5.5979996e+09 | L9: 32018.965 | M9: 3.8486728e-07 | N9: Intercept | O9: -361.91045 | P9: 277.18969 | Q9: =P9*SQRT(G13) -> 619.81498 | R9: -1.3056418 | S9: 0.28277587 | T9: -1244.0517 | U9: 520.23085 | V9: -1244.0517 | W9: 520.23085 | X9: =3.3*Q9/O10 -> 0.10614224 | Y9: =10*Q9/O10 -> 0.32164314
A10: 43838 | B10: 2 | C10: 0.5 | D10: 10120 | E10: =D10-$D$8 -> 9406 | F10: R Square | G10: 0.99990631 | H10: Residual | I10: 3 | J10: 524501.61 | K10: 174833.87 | N10: X Variable 1 | O10: 19270.269 | P10: 107.69217 | R10: 178.93844 | S10: 3.8486728e-07 | T10: 18927.544 | U10: 19612.993 | V10: 18927.544 | W10: 19612.993
A11: 43838 | B11: 2 | C11: 1.25 | D11: 24585 | E11: =D11-$D$8 -> 23871 | F11: Adjusted R Square | G11: 0.99987509 | H11: Total | I11: 4 | J11: 5.5985241e+09
A12: 43838 | B12: 2 | C12: 2.5 | D12: 47890 | E12: =D12-$D$8 -> 47176 | F12: Standard Error | G12: 418.1314
A13: 43838 | B13: 2 | C13: 5 | D13: 96968 | E13: =D13-$D$8 -> 96254 | F13: Observations | G13: 5
A14: 43838 | B14: 3 | C14: 0 | D14: 679 | E14: =D14-$D$14 -> 0 | F14: Regression Statistics | I14: df | J14: SS | K14: MS | L14: F | M14: Significance F | O14: Coefficients | P14: SE | Q14: SD | R14: t Stat | S14: P-value | T14: Lower 95% | U14: Upper 95% | V14: Lower 95.0% | W14: Upper 95.0%
A15: 43838 | B15: 3 | C15: 0.25 | D15: 5019 | E15: =D15-$D$14 -> 4340 | F15: Multiple R | G15: 0.99997486 | H15: Regression | I15: 1 | J15: 4.9201839e+09 | K15: 4.9201839e+09 | L15: 59663.543 | M15: 1.5131465e-07 | N15: Intercept | O15: -106 | P15: 190.37084 | Q15: =P15*SQRT(G19) -> 425.68214 | R15: -0.55680796 | S15: 0.61649953 | T15: -711.84498 | U15: 499.84498 | V15: -711.84498 | W15: 499.84498 | X15: =3.3*Q15/O16 -> 0.077756618 | Y15: =10*Q15/O16 -> 0.23562612
A16: 43838 | B16: 3 | C16: 0.5 | D16: 9565 | E16: =D16-$D$14 -> 8886 | F16: R Square | G16: 0.99994972 | H16: Residual | I16: 3 | J16: 247396.5 | K16: 82465.5 | N16: X Variable 1 | O16: 18066 | P16: 73.961803 | R16: 244.26122 | S16: 1.5131465e-07 | T16: 17830.621 | U16: 18301.379 | V16: 17830.621 | W16: 18301.379
A17: 43838 | B17: 3 | C17: 1.25 | D17: 23512 | E17: =D17-$D$14 -> 22833 | F17: Adjusted R Square | G17: 0.99993296 | H17: Total | I17: 4 | J17: 4.9204313e+09
A18: 43838 | B18: 3 | C18: 2.5 | D18: 45411 | E18: =D18-$D$14 -> 44732 | F18: Standard Error | G18: 287.16807
A19: 43838 | B19: 3 | C19: 5 | D19: 90985 | E19: =D19-$D$14 -> 90306 | F19: Observations | G19: 5
A20: 43789 | B20: 1 | C20: 0 | D20: 85.250256 | E20: =D20-$D$20 -> 0 | F20: Regression Statistics | I20: df | J20: SS | K20: MS | L20: F | M20: Significance F | O20: Coefficients | P20: SE | Q20: SD | R20: t Stat | S20: P-value | T20: Lower 95% | U20: Upper 95% | V20: Lower 95.0% | W20: Upper 95.0%
A21: 43789 | B21: 1 | C21: 0.25 | D21: 2015.8922 | E21: =D21-$D$20 -> 1930.642 | F21: Multiple R | G21: 0.99988705 | H21: Regression | I21: 1 | J21: 7.7822222e+08 | K21: 7.7822222e+08 | L21: 13278.227 | M21: 1.44093e-06 | N21: Intercept | O21: 338.03793 | P21: 160.48929 | Q21: =P21*SQRT(G25) -> 358.86496 | R21: 2.1062959 | S21: 0.1258093 | T21: -172.71061 | U21: 848.78648 | V21: -172.71061 | W21: 848.78648 | X21: =3.3*Q21/O22 -> 0.16482453 | Y21: =10*Q21/O22 -> 0.49946827
A22: 43789 | B22: 1 | C22: 0.5 | D22: 3924.289 | E22: =D22-$D$20 -> 3839.0387 | F22: R Square | G22: 0.99977412 | H22: Residual | I22: 3 | J22: 175826.69 | K22: 58608.896 | N22: X Variable 1 | O22: 7184.9401 | P22: 62.352391 | R22: 115.23119 | S22: 1.44093e-06 | T22: 6986.507 | U22: 7383.3732 | V22: 6986.507 | W22: 7383.3732
A23: 43789 | B23: 1 | C23: 1.25 | D23: 9607.9804 | E23: =D23-$D$20 -> 9522.7301 | F23: Adjusted R Square | G23: 0.99969882 | H23: Total | I23: 4 | J23: 7.7839804e+08
A24: 43789 | B24: 1 | C24: 2.5 | D24: 18631.906 | E24: =D24-$D$20 -> 18546.656 | F24: Standard Error | G24: 242.09274
A25: 43789 | B25: 1 | C25: 5 | D25: 36193.304 | E25: =D25-$D$20 -> 36108.054 | F25: Observations | G25: 5
A26: 43888 | B26: 1 | C26: 0 | D26: 113.00045 | E26: =D26-$D$26 -> 0 | F26: Regression Statistics | I26: df | J26: SS | K26: MS | L26: F | M26: Significance F | O26: Coefficients | P26: SE | Q26: SD | R26: t Stat | S26: P-value | T26: Lower 95% | U26: Upper 95% | V26: Lower 95.0% | W26: Upper 95.0%
A27: 43888 | B27: 1 | C27: 0.25 | D27: 2734.2618 | E27: =D27-$D$26 -> 2621.2613 | F27: Multiple R | G27: 0.99996383 | H27: Regression | I27: 1 | J27: 1.8547388e+09 | K27: 1.8547388e+09 | L27: 41470.799 | M27: 2.6110756e-07 | N27: Intercept | O27: -260.42046 | P27: 140.19562 | Q27: =P27*SQRT(G31) -> 313.48695 | R27: -1.8575505 | S27: 0.16021888 | T27: -706.58551 | U27: 185.74459 | V27: -706.58551 | W27: 185.74459 | X27: =3.3*Q27/O28 -> 0.093265427 | Y27: =10*Q27/O28 -> 0.28262251
A28: 43888 | B28: 1 | C28: 0.5 | D28: 5449.54 | E28: =D28-$D$26 -> 5336.5396 | F28: R Square | G28: 0.99992767 | H28: Residual | I28: 3 | J28: 134171.91 | K28: 44723.971 | N28: X Variable 1 | O28: 11092.073 | P28: 54.468011 | R28: 203.6438 | S28: 2.6110756e-07 | T28: 10918.731 | U28: 11265.415 | V28: 10918.731 | W28: 11265.415
A29: 43888 | B29: 1 | C29: 1.25 | D29: 13728.595 | E29: =D29-$D$26 -> 13615.595 | F29: Adjusted R Square | G29: 0.99990355 | H29: Total | I29: 4 | J29: 1.854873e+09
A30: 43888 | B30: 1 | C30: 2.5 | D30: 27268.253 | E30: =D30-$D$26 -> 27155.253 | F30: Standard Error | G30: 211.48043
A31: 43888 | B31: 1 | C31: 5 | D31: 55456.943 | E31: =D31-$D$26 -> 55343.943 | F31: Observations | G31: 5
A32: 43888 | B32: 2 | C32: 0 | D32: 161.25091 | E32: =D32-$D$32 -> 0 | F32: Regression Statistics | I32: df | J32: SS | K32: MS | L32: F | M32: Significance F | O32: Coefficients | P32: SE | Q32: SD | R32: t Stat | S32: P-value | T32: Lower 95% | U32: Upper 95% | V32: Lower 95.0% | W32: Upper 95.0%
A33: 43888 | B33: 2 | C33: 0.25 | D33: 2444.9594 | E33: =D33-$D$32 -> 2283.7085 | F33: Multiple R | G33: 0.99999394 | H33: Regression | I33: 1 | J33: 1.3525619e+09 | K33: 1.3525619e+09 | L33: 247526.41 | M33: 1.7907383e-08 | N33: Intercept | O33: -31.800456 | P33: 49.004064 | Q33: =P33*SQRT(G37) -> 109.57642 | R33: -0.64893507 | S33: 0.56262988 | T33: -187.75326 | U33: 124.15235 | V33: -187.75326 | W33: 124.15235 | X33: =3.3*Q33/O34 -> 0.038175182 | Y33: =10*Q33/O34 -> 0.11568237
A34: 43888 | B34: 2 | C34: 0.5 | D34: 4824.3146 | E34: =D34-$D$32 -> 4663.0637 | F34: R Square | G34: 0.99998788 | H34: Residual | I34: 3 | J34: 16392.941 | K34: 5464.3138 | N34: X Variable 1 | O34: 9472.1795 | P34: 19.038782 | R34: 497.52026 | S34: 1.7907383e-08 | T34: 9411.5896 | U34: 9532.7694 | V34: 9411.5896 | W34: 9532.7694
A35: 43888 | B35: 2 | C35: 1.25 | D35: 12037.821 | E35: =D35-$D$32 -> 11876.57 | F35: Adjusted R Square | G35: 0.99998384 | H35: Total | I35: 4 | J35: 1.3525783e+09
A36: 43888 | B36: 2 | C36: 2.5 | D36: 23881.704 | E36: =D36-$D$32 -> 23720.453 | F36: Standard Error | G36: 73.920997
A37: 43888 | B37: 2 | C37: 5 | D37: 47444.158 | E37: =D37-$D$32 -> 47282.908 | F37: Observations | G37: 5

Sheet strontium_Sr
A1: Date | B1: No_cal | C1: Std_conc (ppb) | D1: Sr87 (cps) | E1: Sr87 (BLK corrected) | F1: SUMMARY OUTPUT | H1: ANOVA
A2: 43838 | B2: 1 | C2: 0 | D2: 139.75069 | E2: =D2-$D$2 -> 0 | F2: Regression Statistics | I2: df | J2: SS | K2: MS | L2: F | M2: Significance F | O2: Coefficients | P2: SE | Q2: SD | R2: t Stat | S2: P-value | T2: Lower 95% | U2: Upper 95% | V2: Lower 95.0% | W2: Upper 95.0% | X2: LOD (µg/L) | Y2: LOQ (µg/L)
A3: 43838 | B3: 1 | C3: 0.25 | D3: 14178.286 | E3: =D3-$D$2 -> 14038.535 | F3: Multiple R | G3: 0.99997809 | H3: Regression | I3: 1 | J3: 5.3798324e+10 | K3: 5.3798324e+10 | L3: 68467.329 | M3: 1.2309002e-07 | N3: Intercept | O3: -1473.226 | P3: 587.63406 | Q3: =P3*SQRT(G7) -> 1313.9897 | R3: -2.5070467 | S3: 0.087163846 | T3: -3343.3399 | U3: 396.88782 | V3: -3343.3399 | W3: 396.88782 | X3: =3.3*Q3/O4 -> 0.072585553 | Y3: =10*Q3/O4 -> 0.21995622
A4: 43838 | B4: 1 | C4: 0.5 | D4: 29070.555 | E4: =D4-$D$2 -> 28930.804 | F4: R Square | G4: 0.99995619 | H4: Residual | I4: 3 | J4: 2357255.3 | K4: 785751.75 | N4: X Variable 1 | O4: 59738.692 | P4: 228.30426 | R4: 261.66263 | S4: 1.2309002e-07 | T4: 59012.126 | U4: 60465.258 | V4: 59012.126 | W4: 60465.258
A5: 43838 | B5: 1 | C5: 1.25 | D5: 72576.953 | E5: =D5-$D$2 -> 72437.202 | F5: Adjusted R Square | G5: 0.99994158 | H5: Total | I5: 4 | J5: 5.3800681e+10
A6: 43838 | B6: 1 | C6: 2.5 | D6: 147098.76 | E6: =D6-$D$2 -> 146959.01 | F6: Standard Error | G6: 886.42639
A7: 43838 | B7: 1 | C7: 5 | D7: 297925.64 | E7: =D7-$D$2 -> 297785.89 | F7: Observations | G7: 5
A8: 43838 | B8: 2 | C8: 0 | D8: 186.00122 | E8: =D8-$D$8 -> 0 | F8: Regression Statistics | I8: df | J8: SS | K8: MS | L8: F | M8: Significance F | O8: Coefficients | P8: SE | Q8: SD | R8: t Stat | S8: P-value | T8: Lower 95% | U8: Upper 95% | V8: Lower 95.0% | W8: Upper 95.0%
A9: 43838 | B9: 2 | C9: 0.25 | D9: 12956.123 | E9: =D9-$D$8 -> 12770.122 | F9: Multiple R | G9: 0.99998861 | H9: Regression | I9: 1 | J9: 4.1650607e+10 | K9: 4.1650607e+10 | L9: 131737.08 | M9: 4.6120801e-08 | N9: Intercept | O9: -472.52527 | P9: 372.75282 | Q9: =P9*SQRT(G13) -> 833.50064 | R9: -1.2676638 | S9: 0.29436955 | T9: -1658.7911 | U9: 713.74056 | V9: -1658.7911 | W9: 713.74056 | X9: =3.3*Q9/O10 -> 0.05232845 | Y9: =10*Q9/O10 -> 0.15857106
A10: 43838 | B10: 2 | C10: 0.5 | D10: 25817.314 | E10: =D10-$D$8 -> 25631.312 | F10: R Square | G10: 0.99997723 | H10: Residual | I10: 3 | J10: 948493.95 | K10: 316164.65 | N10: X Variable 1 | O10: 52563.225 | P10: 144.81982 | R10: 362.95603 | S10: 4.6120801e-08 | T10: 52102.344 | U10: 53024.107 | V10: 52102.344 | W10: 53024.107
A11: 43838 | B11: 2 | C11: 1.25 | D11: 65986.367 | E11: =D11-$D$8 -> 65800.366 | F11: Adjusted R Square | G11: 0.99996964 | H11: Total | I11: 4 | J11: 4.1651556e+10
A12: 43838 | B12: 2 | C12: 2.5 | D12: 130394.75 | E12: =D12-$D$8 -> 130208.75 | F12: Standard Error | G12: 562.2852
A13: 43838 | B13: 2 | C13: 5 | D13: 262763.47 | E13: =D13-$D$8 -> 262577.47 | F13: Observations | G13: 5
A14: 43838 | B14: 3 | C14: 0 | D14: 255.7523 | E14: =D14-$D$14 -> 0 | F14: Regression Statistics | I14: df | J14: SS | K14: MS | L14: F | M14: Significance F | O14: Coefficients | P14: SE | Q14: SD | R14: t Stat | S14: P-value | T14: Lower 95% | U14: Upper 95% | V14: Lower 95.0% | W14: Upper 95.0%
A15: 43838 | B15: 3 | C15: 0.25 | D15: 12306.299 | E15: =D15-$D$14 -> 12050.546 | F15: Multiple R | G15: 0.99998939 | H15: Regression | I15: 1 | J15: 3.7143856e+10 | K15: 3.7143856e+10 | L15: 141332.33 | M15: 4.1504713e-08 | N15: Intercept | O15: 34.04914 | P15: 339.8498 | Q15: =P15*SQRT(G19) -> 759.92725 | R15: 0.10018879 | S15: 0.92651449 | T15: -1047.5046 | U15: 1115.6029 | V15: -1047.5046 | W15: 1115.6029 | X15: =3.3*Q15/O16 -> 0.050520906 | Y15: =10*Q15/O16 -> 0.15309365
A16: 43838 | B16: 3 | C16: 0.5 | D16: 24860.864 | E16: =D16-$D$14 -> 24605.112 | F16: R Square | G16: 0.99997877 | H16: Residual | I16: 3 | J16: 788436.5 | K16: 262812.17 | N16: X Variable 1 | O16: 49638.064 | P16: 132.03652 | R16: 375.94192 | S16: 4.1504713e-08 | T16: 49217.864 | U16: 50058.263 | V16: 49217.864 | W16: 50058.263
A17: 43838 | B17: 3 | C17: 1.25 | D17: 63062.134 | E17: =D17-$D$14 -> 62806.382 | F17: Adjusted R Square | G17: 0.9999717 | H17: Total | I17: 4 | J17: 3.7144644e+10
A18: 43838 | B18: 3 | C18: 2.5 | D18: 124490.91 | E18: =D18-$D$14 -> 124235.16 | F18: Standard Error | G18: 512.65209
A19: 43838 | B19: 3 | C19: 5 | D19: 248290.4 | E19: =D19-$D$14 -> 248034.65 | F19: Observations | G19: 5
A20: 43789 | B20: 1 | C20: 0 | D20: 95.750322 | E20: =D20-$D$20 -> 0 | F20: Regression Statistics | I20: df | J20: SS | K20: MS | L20: F | M20: Significance F | O20: Coefficients | P20: SE | Q20: SD | R20: t Stat | S20: P-value | T20: Lower 95% | U20: Upper 95% | V20: Lower 95.0% | W20: Upper 95.0%
A21: 43789 | B21: 1 | C21: 0.25 | D21: 12118.14 | E21: =D21-$D$20 -> 12022.389 | F21: Multiple R | G21: 0.99977858 | H21: Regression | I21: 1 | J21: 2.828146e+10 | K21: 2.828146e+10 | L21: 6772.3079 | M21: 3.9548944e-06 | N21: Intercept | O21: 2851.0626 | P21: 1354.7116 | Q21: =P21*SQRT(G25) -> 3029.2272 | R21: 2.1045532 | S21: 0.126018 | T21: -1460.2343 | U21: 7162.3595 | V21: -1460.2343 | W21: 7162.3595 | X21: =3.3*Q21/O22 -> 0.23079348 | Y21: =10*Q21/O22 -> 0.69937418
A22: 43789 | B22: 1 | C22: 0.5 | D22: 23733.453 | E22: =D22-$D$20 -> 23637.702 | F22: R Square | G22: 0.99955722 | H22: Residual | I22: 3 | J22: 12528134 | K22: 4176044.6 | N22: X Variable 1 | O22: 43313.398 | P22: 526.32489 | R22: 82.294033 | S22: 3.9548944e-06 | T22: 41638.397 | U22: 44988.398 | V22: 41638.397 | W22: 44988.398
A23: 43789 | B23: 1 | C23: 1.25 | D23: 58870.094 | E23: =D23-$D$20 -> 58774.344 | F23: Adjusted R Square | G23: 0.99940962 | H23: Total | I23: 4 | J23: 2.8293988e+10
A24: 43789 | B24: 1 | C24: 2.5 | D24: 113272.46 | E24: =D24-$D$20 -> 113176.7 | F24: Standard Error | G24: 2043.5373
A25: 43789 | B25: 1 | C25: 5 | D25: 218217.2 | E25: =D25-$D$20 -> 218121.45 | F25: Observations | G25: 5
A26: 43888 | B26: 1 | C26: 0 | D26: 114.75046 | E26: =D26-$D$26 -> 0 | F26: Regression Statistics | I26: df | J26: SS | K26: MS | L26: F | M26: Significance F | O26: Coefficients | P26: SE | Q26: SD | R26: t Stat | S26: P-value | T26: Lower 95% | U26: Upper 95% | V26: Lower 95.0% | W26: Upper 95.0%
A27: 43888 | B27: 1 | C27: 0.25 | D27: 16442.46 | E27: =D27-$D$26 -> 16327.709 | F27: Multiple R | G27: 0.99999787 | H27: Regression | I27: 1 | J27: 6.7318275e+10 | K27: 6.7318275e+10 | L27: 702663.39 | M27: 3.7441008e-09 | N27: Intercept | O27: -434.02192 | P27: 205.19043 | Q27: =P27*SQRT(G31) -> 458.81976 | R27: -2.1152152 | S27: 0.12474762 | T27: -1087.0295 | U27: 218.98562 | V27: -1087.0295 | W27: 218.98562 | X27: =3.3*Q27/O28 -> 0.022657825 | Y27: =10*Q27/O28 -> 0.068660076
A28: 43888 | B28: 1 | C28: 0.5 | D28: 33212.068 | E28: =D28-$D$26 -> 33097.318 | F28: R Square | G28: 0.99999573 | H28: Residual | I28: 3 | J28: 287413.33 | K28: 95804.444 | N28: X Variable 1 | O28: 66824.825 | P28: 79.719427 | R28: 838.2502 | S28: 3.7441008e-09 | T28: 66571.122 | U28: 67078.528 | V28: 66571.122 | W28: 67078.528
A29: 43888 | B29: 1 | C29: 1.25 | D29: 82795.486 | E29: =D29-$D$26 -> 82680.735 | F29: Adjusted R Square | G29: 0.99999431 | H29: Total | I29: 4 | J29: 6.7318563e+10
A30: 43888 | B30: 1 | C30: 2.5 | D30: 167047.64 | E30: =D30-$D$26 -> 166932.89 | F30: Standard Error | G30: 309.52293
A31: 43888 | B31: 1 | C31: 5 | D31: 333741.83 | E31: =D31-$D$26 -> 333627.08 | F31: Observations | G31: 5
A32: 43888 | B32: 2 | C32: 0 | D32: 191.25129 | E32: =D32-$D$32 -> 0 | F32: Regression Statistics | I32: df | J32: SS | K32: MS | L32: F | M32: Significance F | O32: Coefficients | P32: SE | Q32: SD | R32: t Stat | S32: P-value | T32: Lower 95% | U32: Upper 95% | V32: Lower 95.0% | W32: Upper 95.0%
A33: 43888 | B33: 2 | C33: 0.25 | D33: 15027.9 | E33: =D33-$D$32 -> 14836.649 | F33: Multiple R | G33: 0.9999909 | H33: Regression | I33: 1 | J33: 5.2327703e+10 | K33: 5.2327703e+10 | L33: 164915.19 | M33: 3.2928374e-08 | N33: Intercept | O33: 260.05258 | P33: 373.42191 | Q33: =P33*SQRT(G37) -> 834.99677 | R33: 0.6964042 | S33: 0.53628297 | T33: -928.34258 | U33: 1448.4478 | V33: -928.34258 | W33: 1448.4478 | X33: =3.3*Q33/O34 -> 0.046769374 | Y33: =10*Q33/O34 -> 0.14172538
A34: 43888 | B34: 2 | C34: 0.5 | D34: 29763.726 | E34: =D34-$D$32 -> 29572.475 | F34: R Square | G34: 0.99998181 | H34: Residual | I34: 3 | J34: 951902.08 | K34: 317300.69 | N34: X Variable 1 | O34: 58916.532 | P34: 145.07977 | R34: 406.09751 | S34: 3.2928374e-08 | T34: 58454.824 | U34: 59378.241 | V34: 58454.824 | W34: 59378.241
A35: 43888 | B35: 2 | C35: 1.25 | D35: 74847.649 | E35: =D35-$D$32 -> 74656.397 | F35: Adjusted R Square | G35: 0.99997575 | H35: Total | I35: 4 | J35: 5.2328655e+10
A36: 43888 | B36: 2 | C36: 2.5 | D36: 147168.95 | E36: =D36-$D$32 -> 146977.7 | F36: Standard Error | G36: 563.2945
A37: 43888 | B37: 2 | C37: 5 | D37: 295155.35 | E37: =D37-$D$32 -> 294964.1 | F37: Observations | G37: 5

Sheet molybdenum_Mo
A1: Date | B1: No_cal | C1: Std_conc (ppb) | D1: Mo (cps) | E1: Mo (BLK corrected) | F1: SUMMARY OUTPUT | H1: ANOVA
A2: 43838 | B2: 1 | C2: 0 | D2: 6 | E2: =D2-$D$2 -> 0 | F2: Regression Statistics | I2: df | J2: SS | K2: MS | L2: F | M2: Significance F | O2: Coefficients | P2: SE | Q2: SD | R2: t Stat | S2: P-value | T2: Lower 95% | U2: Upper 95% | V2: Lower 95.0% | W2: Upper 95.0% | X2: LOD (µg/L) | Y2: LOQ (µg/L)
A3: 43838 | B3: 1 | C3: 0.5 | D3: 5378 | E3: =D3-$D$2 -> 5372 | F3: Multiple R | G3: 0.999989 | H3: Regression | I3: 1 | J3: 7.750022e+09 | K3: 7.750022e+09 | L3: 136394 | M3: 4.3779056e-08 | N3: Intercept | O3: -390.87065 | P3: 158.02221 | Q3: =P3*SQRT(G7) -> 353.34839 | R3: -2.4735172 | S3: 0.089784006 | T3: -893.76783 | U3: 112.02654 | V3: -893.76783 | W3: 112.02654 | X3: =3.3*Q3/O4 -> 0.10285473 | Y3: =10*Q3/O4 -> 0.31168099
A4: 43838 | B4: 1 | C4: 1 | D4: 11055 | E4: =D4-$D$2 -> 11049 | F4: R Square | G4: 0.99997801 | H4: Residual | I4: 3 | J4: 170462.53 | K4: 56820.843 | N4: X Variable 1 | O4: 11336.861 | P4: 30.696947 | R4: 369.31558 | S4: 4.3779056e-08 | T4: 11239.169 | U4: 11434.552 | V4: 11239.169 | W4: 11434.552
A5: 43838 | B5: 1 | C5: 2.5 | D5: 27949 | E5: =D5-$D$2 -> 27943 | F5: Adjusted R Square | G5: 0.99997067 | H5: Total | I5: 4 | J5: 7.7501924e+09
A6: 43838 | B6: 1 | C6: 5 | D6: 55947 | E6: =D6-$D$2 -> 55941 | F6: Standard Error | G6: 238.37123
A7: 43838 | B7: 1 | C7: 10 | D7: 113147 | E7: =D7-$D$2 -> 113141 | F7: Observations | G7: 5
A8: 43838 | B8: 2 | C8: 0 | D8: 19 | E8: =D8-$D$8 -> 0 | F8: Regression Statistics | I8: df | J8: SS | K8: MS | L8: F | M8: Significance F | O8: Coefficients | P8: SE | Q8: SD | R8: t Stat | S8: P-value | T8: Lower 95% | U8: Upper 95% | V8: Lower 95.0% | W8: Upper 95.0%
A9: 43838 | B9: 2 | C9: 0.5 | D9: 4973.5609 | E9: =D9-$D$8 -> 4954.5609 | F9: Multiple R | G9: 0.99992785 | H9: Regression | I9: 1 | J9: 6.5370718e+09 | K9: 6.5370718e+09 | L9: 20786.701 | M9: 7.3572781e-07 | N9: Intercept | O9: -365.89423 | P9: 371.76039 | Q9: =P9*SQRT(G13) -> 831.28151 | R9: -0.98422058 | S9: 0.39757857 | T9: -1549.0017 | U9: 817.21326 | V9: -1549.0017 | W9: 817.21326 | X9: =3.3*Q9/O10 -> 0.26346874 | Y9: =10*Q9/O10 -> 0.79839011
A10: 43838 | B10: 2 | C10: 1 | D10: 10181.796 | E10: =D10-$D$8 -> 10162.796 | F10: R Square | G10: 0.9998557 | H10: Residual | I10: 3 | J10: 943450.09 | K10: 314483.36 | N10: X Variable 1 | O10: 10411.972 | P10: 72.217123 | R10: 144.17594 | S10: 7.3572781e-07 | T10: 10182.144 | U10: 10641.799 | V10: 10182.144 | W10: 10641.799
A11: 43838 | B11: 2 | C11: 2.5 | D11: 25964.996 | E11: =D11-$D$8 -> 25945.996 | F11: Adjusted R Square | G11: 0.9998076 | H11: Total | I11: 4 | J11: 6.5380152e+09
A12: 43838 | B12: 2 | C12: 5 | D12: 50862.436 | E12: =D12-$D$8 -> 50843.436 | F12: Standard Error | G12: 560.78816
A13: 43838 | B13: 2 | C13: 10 | D13: 104110.2 | E13: =D13-$D$8 -> 104091.2 | F13: Observations | G13: 5
A14: 43838 | B14: 3 | C14: 0 | D14: 52.640485 | E14: =D14-$D$14 -> 0 | F14: Regression Statistics | I14: df | J14: SS | K14: MS | L14: F | M14: Significance F | O14: Coefficients | P14: SE | Q14: SD | R14: t Stat | S14: P-value | T14: Lower 95% | U14: Upper 95% | V14: Lower 95.0% | W14: Upper 95.0%
A15: 43838 | B15: 3 | C15: 0.5 | D15: 4921.766 | E15: =D15-$D$14 -> 4869.1255 | F15: Multiple R | G15: 0.99998991 | H15: Regression | I15: 1 | J15: 6.0808424e+09 | K15: 6.0808424e+09 | L15: 148617.87 | M15: 3.8490512e-08 | N15: Intercept | O15: -116.19774 | P15: 134.0944 | Q15: =P15*SQRT(G19) -> 299.84419 | R15: -0.86653687 | S15: 0.44994428 | T15: -542.94597 | U15: 310.55049 | V15: -542.94597 | W15: 310.55049 | X15: =3.3*Q15/O16 -> 0.098534057 | Y15: =10*Q15/O16 -> 0.29858805
A16: 43838 | B16: 3 | C16: 1 | D16: 9953.3296 | E16: =D16-$D$14 -> 9900.6891 | F16: R Square | G16: 0.99997981 | H16: Residual | I16: 3 | J16: 122747.87 | K16: 40915.958 | N16: X Variable 1 | O16: 10042.069 | P16: 26.048799 | R16: 385.50988 | S16: 3.8490512e-08 | T16: 9959.1705 | U16: 10124.968 | V16: 9959.1705 | W16: 10124.968
A17: 43838 | B17: 3 | C17: 2.5 | D17: 25279.848 | E17: =D17-$D$14 -> 25227.208 | F17: Adjusted R Square | G17: 0.99997309 | H17: Total | I17: 4 | J17: 6.0809651e+09
A18: 43838 | B18: 3 | C18: 5 | D18: 49902.622 | E18: =D18-$D$14 -> 49849.982 | F18: Standard Error | G18: 202.27693
A19: 43838 | B19: 3 | C19: 10 | D19: 100423.97 | E19: =D19-$D$14 -> 100371.33 | F19: Observations | G19: 5
A20: 43789 | B20: 1 | C20: 0 | D20: 11.236085 | E20: =D20-$D$20 -> 0 | F20: Regression Statistics | I20: df | J20: SS | K20: MS | L20: F | M20: Significance F | O20: Coefficients | P20: SE | Q20: SD | R20: t Stat | S20: P-value | T20: Lower 95% | U20: Upper 95% | V20: Lower 95.0% | W20: Upper 95.0%
A21: 43789 | B21: 1 | C21: 0.5 | D21: 6170.4015 | E21: =D21-$D$20 -> 6159.1654 | F21: Multiple R | G21: 0.99989565 | H21: Regression | I21: 1 | J21: 7.476137e+09 | K21: 7.476137e+09 | L21: 14372.54 | M21: 1.2795631e-06 | N21: Intercept | O21: 1215.4771 | P21: 478.11916 | Q21: =P21*SQRT(G25) -> 1069.1069 | R21: 2.5422053 | S21: 0.084516396 | T21: -306.11149 | U21: 2737.0656 | V21: -306.11149 | W21: 2737.0656 | X21: =3.3*Q21/O22 -> 0.31685103 | Y21: =10*Q21/O22 -> 0.96015463
A22: 43789 | B22: 1 | C22: 1 | D22: 12066.585 | E22: =D22-$D$20 -> 12055.349 | F22: R Square | G22: 0.99979131 | H22: Residual | I22: 3 | J22: 1560504.4 | K22: 520168.12 | N22: X Variable 1 | O22: 11134.737 | P22: 92.878076 | R22: 119.88553 | S22: 1.2795631e-06 | T22: 10839.158 | U22: 11430.317 | V22: 10839.158 | W22: 11430.317
A23: 43789 | B23: 1 | C23: 2.5 | D23: 29821.29 | E23: =D23-$D$20 -> 29810.054 | F23: Adjusted R Square | G23: 0.99972175 | H23: Total | I23: 4 | J23: 7.4776975e+09
A24: 43789 | B24: 1 | C24: 5 | D24: 57479.548 | E24: =D24-$D$20 -> 57468.312 | F24: Standard Error | G24: 721.22681
A25: 43789 | B25: 1 | C25: 10 | D25: 112155.75 | E25: =D25-$D$20 -> 112144.51 | F25: Observations | G25: 5
A26: 43888 | B26: 1 | C26: 0 | D26: 12.979345 | E26: =D26-$D$26 -> 0 | F26: Regression Statistics | I26: df | J26: SS | K26: MS | L26: F | M26: Significance F | O26: Coefficients | P26: SE | Q26: SD | R26: t Stat | S26: P-value | T26: Lower 95% | U26: Upper 95% | V26: Lower 95.0% | W26: Upper 95.0%
A27: 43888 | B27: 1 | C27: 0.5 | D27: 7520.959 | E27: =D27-$D$26 -> 7507.9796 | F27: Multiple R | G27: 0.9999969 | H27: Regression | I27: 1 | J27: 1.3696622e+10 | K27: 1.3696622e+10 | L27: 483327.09 | M27: 6.5630513e-09 | N27: Intercept | O27: 64.760166 | P27: 111.59647 | Q27: =P27*SQRT(G31) -> 249.53729 | R27: 0.58030659 | S27: 0.60242281 | T27: -290.3896 | U27: 419.90993 | V27: -290.3896 | W27: 419.90993 | X27: =3.3*Q27/O28 -> 0.05463882 | Y27: =10*Q27/O28 -> 0.16557218
A28: 43888 | B28: 1 | C28: 1 | D28: 15259.826 | E28: =D28-$D$26 -> 15246.847 | F28: R Square | G28: 0.99999379 | H28: Residual | I28: 3 | J28: 85014.615 | K28: 28338.205 | N28: X Variable 1 | O28: 15071.209 | P28: 21.678414 | R28: 695.2173 | S28: 6.5630513e-09 | T28: 15002.218 | U28: 15140.199 | V28: 15002.218 | W28: 15140.199
A29: 43888 | B29: 1 | C29: 2.5 | D29: 37879.894 | E29: =D29-$D$26 -> 37866.914 | F29: Adjusted R Square | G29: 0.99999172 | H29: Total | I29: 4 | J29: 1.3696707e+10
A30: 43888 | B30: 1 | C30: 5 | D30: 75223.535 | E30: =D30-$D$26 -> 75210.556 | F30: Standard Error | G30: 168.33955
A31: 43888 | B31: 1 | C31: 10 | D31: 150857.45 | E31: =D31-$D$26 -> 150844.47 | F31: Observations | G31: 5
A32: 43888 | B32: 2 | C32: 0 | D32: 36.201982 | E32: =D32-$D$32 -> 0 | F32: Regression Statistics | I32: df | J32: SS | K32: MS | L32: F | M32: Significance F | O32: Coefficients | P32: SE | Q32: SD | R32: t Stat | S32: P-value | T32: Lower 95% | U32: Upper 95% | V32: Lower 95.0% | W32: Upper 95.0%
A33: 43888 | B33: 2 | C33: 0.5 | D33: 6942.8616 | E33: =D33-$D$32 -> 6906.6596 | F33: Multiple R | G33: 0.99994688 | H33: Regression | I33: 1 | J33: 1.0988847e+10 | K33: 1.0988847e+10 | L33: 28237.465 | M33: 4.6470444e-07 | N33: Intercept | O33: 658.75313 | P33: 413.5495 | Q33: =P33*SQRT(G37) -> 924.72479 | R33: 1.5929245 | S33: 0.2094252 | T33: -657.34594 | U33: 1974.8522 | V33: -657.34594 | W33: 1974.8522 | X33: =3.3*Q33/O34 -> 0.22605235 | Y33: =10*Q33/O34 -> 0.68500712
A34: 43888 | B34: 2 | C34: 1 | D34: 13904.412 | E34: =D34-$D$32 -> 13868.21 | F34: R Square | G34: 0.99989377 | H34: Residual | I34: 3 | J34: 1167475.3 | K34: 389158.42 | N34: X Variable 1 | O34: 13499.492 | P34: 80.334956 | R34: 168.04007 | S34: 4.6470444e-07 | T34: 13243.83 | U34: 13755.153 | V34: 13243.83 | W34: 13755.153
A35: 43888 | B35: 2 | C35: 2.5 | D35: 35051.575 | E35: =D35-$D$32 -> 35015.373 | F35: Adjusted R Square | G35: 0.99985836 | H35: Total | I35: 4 | J35: 1.0990015e+10
A36: 43888 | B36: 2 | C36: 5 | D36: 68756.133 | E36: =D36-$D$32 -> 68719.931 | F36: Standard Error | G36: 623.82564
A37: 43888 | B37: 2 | C37: 10 | D37: 135310.13 | E37: =D37-$D$32 -> 135273.93 | F37: Observations | G37: 5

Sheet antimony_Sb
A1: Date | B1: No_cal | C1: Std_conc (ppb) | D1: Sb (cps) | E1: Sb (BLK corrected) | F1: SUMMARY OUTPUT | H1: ANOVA
A2: 43838 | B2: 1 | C2: 0 | D2: 26.500026 | E2: =D2-$D$2 -> 0 | F2: Regression Statistics | I2: df | J2: SS | K2: MS | L2: F | M2: Significance F | O2: Coefficients | P2: SE | Q2: SD | R2: t Stat | S2: P-value | T2: Lower 95% | U2: Upper 95% | V2: Lower 95.0% | W2: Upper 95.0% | X2: LOD (µg/L) | Y2: LOQ (µg/L)
A3: 43838 | B3: 1 | C3: 0.01 | D3: 152.00081 | E3: =D3-$D$2 -> 125.50079 | F3: Multiple R | G3: 0.9999135 | H3: Regression | I3: 1 | J3: 3690764.9 | K3: 3690764.9 | L3: 17339.376 | M3: 9.6567365e-07 | N3: Intercept | O3: -2.6112803 | P3: 9.671765 | Q3: =P3*SQRT(G7) -> 21.626724 | R3: -0.26999005 | S3: 0.80467519 | T3: -33.391153 | U3: 28.168592 | V3: -33.391153 | W3: 28.168592 | X3: =3.3*Q3/O4 -> 0.0057694596 | Y3: =10*Q3/O4 -> 0.017483211
A4: 43838 | B4: 1 | C4: 0.02 | D4: 252.75224 | E4: =D4-$D$2 -> 226.25222 | F4: R Square | G4: 0.99982701 | H4: Residual | I4: 3 | J4: 638.5636 | K4: 212.85453 | N4: X Variable 1 | O4: 12369.995 | P4: 93.940486 | R4: 131.67907 | S4: 9.6567365e-07 | T4: 12071.035 | U4: 12668.956 | V4: 12071.035 | W4: 12668.956
A5: 43838 | B5: 1 | C5: 0.05 | D5: 658.7652 | E5: =D5-$D$2 -> 632.26517 | F5: Adjusted R Square | G5: 0.99976935 | H5: Total | I5: 4 | J5: 3691403.4
A6: 43838 | B6: 1 | C6: 0.1 | D6: 1261.3058 | E6: =D6-$D$2 -> 1234.8058 | F6: Standard Error | G6: 14.589535
A7: 43838 | B7: 1 | C7: 0.2 | D7: 2495.2179 | E7: =D7-$D$2 -> 2468.7179 | F7: Observations | G7: 5
A8: 43838 | B8: 2 | C8: 0 | D8: 32.250036 | E8: =D8-$D$8 -> 0 | F8: Regression Statistics | I8: df | J8: SS | K8: MS | L8: F | M8: Significance F | O8: Coefficients | P8: SE | Q8: SD | R8: t Stat | S8: P-value | T8: Lower 95% | U8: Upper 95% | V8: Lower 95.0% | W8: Upper 95.0%
A9: 43838 | B9: 2 | C9: 0.01 | D9: 147.50076 | E9: =D9-$D$8 -> 115.25073 | F9: Multiple R | G9: 0.9999425 | H9: Regression | I9: 1 | J9: 3140858.7 | K9: 3140858.7 | L9: 26083.474 | M9: 5.2343487e-07 | N9: Intercept | O9: -3.3595591 | P9: 7.2745437 | Q9: =P9*SQRT(G13) -> 16.266374 | R9: -0.46182403 | S9: 0.67563682 | T9: -26.510404 | U9: 19.791286 | V9: -26.510404 | W9: 19.791286 | X9: =3.3*Q9/O10 -> 0.00470402 | Y9: =10*Q9/O10 -> 0.014254606
A10: 43838 | B10: 2 | C10: 0.02 | D10: 244.25209 | E10: =D10-$D$8 -> 212.00205 | F10: R Square | G10: 0.999885 | H10: Residual | I10: 3 | J10: 361.24697 | K10: 120.41566 | N10: X Variable 1 | O10: 11411.311 | P10: 70.656615 | R10: 161.50379 | S10: 5.2343487e-07 | T10: 11186.45 | U10: 11636.172 | V10: 11186.45 | W10: 11636.172
A11: 43838 | B11: 2 | C11: 0.05 | D11: 612.01314 | E11: =D11-$D$8 -> 579.7631 | F11: Adjusted R Square | G11: 0.99984666 | H11: Total | I11: 4 | J11: 3141219.9
A12: 43838 | B12: 2 | C12: 0.1 | D12: 1165.7976 | E12: =D12-$D$8 -> 1133.5475 | F12: Standard Error | G12: 10.973407
A13: 43838 | B13: 2 | C13: 0.2 | D13: 2311.187 | E13: =D13-$D$8 -> 2278.937 | F13: Observations | G13: 5
A14: 43838 | B14: 3 | C14: 0 | D14: 27.250029 | E14: =D14-$D$14 -> 0 | F14: Regression Statistics | I14: df | J14: SS | K14: MS | L14: F | M14: Significance F | O14: Coefficients | P14: SE | Q14: SD | R14: t Stat | S14: P-value | T14: Lower 95% | U14: Upper 95% | V14: Lower 95.0% | W14: Upper 95.0%
